Started by upstream project "[8mha:////4BvBWfHru0odOsD08n7MCY0vMikt5HnV6lIQKeCDLidsAAAAoB+LCAAAAAAAAP9b85aBtbiIQTGjNKU4P08vOT+vOD8nVc83PyU1x6OyILUoJzMv2y+/JJUBAhiZGBgqihhk0NSjKDWzXb3RdlLBUSYGJk8GtpzUvPSSDB8G5tKinBIGIZ+sxLJE/ZzEvHT94JKizLx0a6BxUmjGOUNodHsLgAy+EgYR/az8JH2//NzElPjc1JLElMSSRH0Apm6X38kAAAA=[0mNomad_metadata" build number [8mha:////4Pxs4Tk8gV9lUsKiac7qqeG4eScobvNk4LaCx1PTJNkjAAAAoh+LCAAAAAAAAP9b85aBtbiIQTGjNKU4P08vOT+vOD8nVc83PyU1x6OyILUoJzMv2y+/JJUBAhiZGBgqihhk0NSjKDWzXb3RdlLBUSYGJk8GtpzUvPSSDB8G5tKinBIGIZ+sxLJE/ZzEvHT94JKizLx0a6BxUmjGOUNodHsLgAymEgYx/az8JH2//NzElPjc1JLElMSSRH0jAwAOlgxKywAAAA==[0m20
originally caused by:
 Started by user [8mha:////4PcHjBgrWG0E1fxRNX+R9P5tz2uFEG3+jieYc2DKk7uAAAAAlx+LCAAAAAAAAP9b85aBtbiIQTGjNKU4P08vOT+vOD8nVc83PyU1x6OyILUoJzMv2y+/JJUBAhiZGBgqihhk0NSjKDWzXb3RdlLBUSYGJk8GtpzUvPSSDB8G5tKinBIGIZ+sxLJE/ZzEvHT94JKizLx0a6BxUmjGOUNodHsLgAzuEgZu/dLi1CL9ovyMzBIAOOgHy8AAAAA=[0mROHIT GUPTA
Started by user [8mha:////4PcHjBgrWG0E1fxRNX+R9P5tz2uFEG3+jieYc2DKk7uAAAAAlx+LCAAAAAAAAP9b85aBtbiIQTGjNKU4P08vOT+vOD8nVc83PyU1x6OyILUoJzMv2y+/JJUBAhiZGBgqihhk0NSjKDWzXb3RdlLBUSYGJk8GtpzUvPSSDB8G5tKinBIGIZ+sxLJE/ZzEvHT94JKizLx0a6BxUmjGOUNodHsLgAzuEgZu/dLi1CL9ovyMzBIAOOgHy8AAAAA=[0mROHIT GUPTA
Running as SYSTEM
Building in workspace C:\Users\GuptaR\.jenkins\workspace\Nomad_method
[Nomad_method] $ cmd /c call C:\Users\GuptaR\AppData\Local\Temp\jenkins4884369760937201185.bat

C:\Users\GuptaR\.jenkins\workspace\Nomad_method>python method_v11.py 
initializing_method_repo
Traceback (most recent call last):
  File "C:\Users\GuptaR\AppData\Local\Programs\Python\Python39\lib\site-packages\urllib3\connection.py", line 174, in _new_conn
    conn = connection.create_connection(
  File "C:\Users\GuptaR\AppData\Local\Programs\Python\Python39\lib\site-packages\urllib3\util\connection.py", line 95, in create_connection
    raise err
  File "C:\Users\GuptaR\AppData\Local\Programs\Python\Python39\lib\site-packages\urllib3\util\connection.py", line 85, in create_connection
    sock.connect(sa)
TimeoutError: [WinError 10060] A connection attempt failed because the connected party did not properly respond after a period of time, or established connection failed because connected host has failed to respond

During handling of the above exception, another exception occurred:

Traceback (most recent call last):
  File "C:\Users\GuptaR\AppData\Local\Programs\Python\Python39\lib\site-packages\urllib3\connectionpool.py", line 703, in urlopen
    httplib_response = self._make_request(
  File "C:\Users\GuptaR\AppData\Local\Programs\Python\Python39\lib\site-packages\urllib3\connectionpool.py", line 398, in _make_request
    conn.request(method, url, **httplib_request_kw)
  File "C:\Users\GuptaR\AppData\Local\Programs\Python\Python39\lib\site-packages\urllib3\connection.py", line 239, in request
    super(HTTPConnection, self).request(method, url, body=body, headers=headers)
  File "C:\Users\GuptaR\AppData\Local\Programs\Python\Python39\lib\http\client.py", line 1285, in request
    self._send_request(method, url, body, headers, encode_chunked)
  File "C:\Users\GuptaR\AppData\Local\Programs\Python\Python39\lib\http\client.py", line 1331, in _send_request
    self.endheaders(body, encode_chunked=encode_chunked)
  File "C:\Users\GuptaR\AppData\Local\Programs\Python\Python39\lib\http\client.py", line 1280, in endheaders
    self._send_output(message_body, encode_chunked=encode_chunked)
  File "C:\Users\GuptaR\AppData\Local\Programs\Python\Python39\lib\http\client.py", line 1040, in _send_output
    self.send(msg)
  File "C:\Users\GuptaR\AppData\Local\Programs\Python\Python39\lib\http\client.py", line 980, in send
    self.connect()
  File "C:\Users\GuptaR\AppData\Local\Programs\Python\Python39\lib\site-packages\urllib3\connection.py", line 205, in connect
    conn = self._new_conn()
  File "C:\Users\GuptaR\AppData\Local\Programs\Python\Python39\lib\site-packages\urllib3\connection.py", line 186, in _new_conn
    raise NewConnectionError(
urllib3.exceptions.NewConnectionError: <urllib3.connection.HTTPConnection object at 0x000002727DEA8FA0>: Failed to establish a new connection: [WinError 10060] A connection attempt failed because the connected party did not properly respond after a period of time, or established connection failed because connected host has failed to respond

During handling of the above exception, another exception occurred:

Traceback (most recent call last):
  File "C:\Users\GuptaR\AppData\Local\Programs\Python\Python39\lib\site-packages\requests\adapters.py", line 439, in send
    resp = conn.urlopen(
  File "C:\Users\GuptaR\AppData\Local\Programs\Python\Python39\lib\site-packages\urllib3\connectionpool.py", line 785, in urlopen
    retries = retries.increment(
  File "C:\Users\GuptaR\AppData\Local\Programs\Python\Python39\lib\site-packages\urllib3\util\retry.py", line 592, in increment
    raise MaxRetryError(_pool, url, error or ResponseError(cause))
urllib3.exceptions.MaxRetryError: HTTPConnectionPool(host='nomad-lab.eu', port=80): Max retries exceeded with url: /prod/rae/api/repo/quantity/upload_id?query=%7B%22%24and%22%3A+%5B%7B%22dft.quantities%22%3A+%5B%22section_workflow%22%2C+%22section_metadata%22%2C+%22section_run%22%5D%7D%2C+%7B%22domain%22%3A+%22dft%22%7D%5D%7D (Caused by NewConnectionError('<urllib3.connection.HTTPConnection object at 0x000002727DEA8FA0>: Failed to establish a new connection: [WinError 10060] A connection attempt failed because the connected party did not properly respond after a period of time, or established connection failed because connected host has failed to respond'))

During handling of the above exception, another exception occurred:

Traceback (most recent call last):
  File "C:\Users\GuptaR\.jenkins\workspace\Nomad_method\method_v11.py", line 101, in <module>
    for i, result in enumerate(results):
  File "C:\Users\GuptaR\AppData\Local\Programs\Python\Python39\lib\_collections_abc.py", line 984, in __iter__
    v = self[i]
  File "C:\Users\GuptaR\AppData\Roaming\Python\Python39\site-packages\nomad\client.py", line 524, in __getitem__
    if key >= self.__len__():
  File "C:\Users\GuptaR\AppData\Roaming\Python\Python39\site-packages\nomad\client.py", line 534, in __len__
    self.call_api()
  File "C:\Users\GuptaR\AppData\Roaming\Python\Python39\site-packages\nomad\client.py", line 471, in call_api
    self._create_initial_proc_state()
  File "C:\Users\GuptaR\AppData\Roaming\Python\Python39\site-packages\nomad\client.py", line 415, in _create_initial_proc_state
    response = requests.get(
  File "C:\Users\GuptaR\AppData\Local\Programs\Python\Python39\lib\site-packages\requests\api.py", line 75, in get
    return request('get', url, params=params, **kwargs)
  File "C:\Users\GuptaR\AppData\Local\Programs\Python\Python39\lib\site-packages\requests\api.py", line 61, in request
    return session.request(method=method, url=url, **kwargs)
  File "C:\Users\GuptaR\AppData\Local\Programs\Python\Python39\lib\site-packages\requests\sessions.py", line 542, in request
    resp = self.send(prep, **send_kwargs)
  File "C:\Users\GuptaR\AppData\Local\Programs\Python\Python39\lib\site-packages\requests\sessions.py", line 655, in send
    r = adapter.send(request, **kwargs)
  File "C:\Users\GuptaR\AppData\Local\Programs\Python\Python39\lib\site-packages\requests\adapters.py", line 516, in send
    raise ConnectionError(e, request=request)
requests.exceptions.ConnectionError: HTTPConnectionPool(host='nomad-lab.eu', port=80): Max retries exceeded with url: /prod/rae/api/repo/quantity/upload_id?query=%7B%22%24and%22%3A+%5B%7B%22dft.quantities%22%3A+%5B%22section_workflow%22%2C+%22section_metadata%22%2C+%22section_run%22%5D%7D%2C+%7B%22domain%22%3A+%22dft%22%7D%5D%7D (Caused by NewConnectionError('<urllib3.connection.HTTPConnection object at 0x000002727DEA8FA0>: Failed to establish a new connection: [WinError 10060] A connection attempt failed because the connected party did not properly respond after a period of time, or established connection failed because connected host has failed to respond'))

C:\Users\GuptaR\.jenkins\workspace\Nomad_method>exit 1 
Build step 'Execute Windows batch command' marked build as failure
Finished: FAILURE
